<?xml version="1.0"?>
<robot name="my_robot" xmlns:xacro="http://www.ros.org/wiki/xacro">

    <xacro:include filename="$(find my_robot_description)/urdf/wheels.xacro"/>
    <xacro:wheels wheel_radius="0.1" wheel_offset_x="0.4" wheel_offset_y="0.4"/>

    <!-- Robot body -->
    <link name="base_link">
        <visual>
            <origin xyz="0 0 0.25" rpy="0 0 0"/>
            <geometry>
                <box size="1 1 0.5"/>
            </geometry>
            <material name="blue">
                <color rgba="0 0 1 1"/>
            </material>
        </visual>
    </link>

    <!-- Slider on top of the body -->
    <link name="slider_link">
        <visual>
            <origin xyz="0 0 0.5" rpy="0 0 0"/>
            <geometry>
                <box size="0.4 0.2 0.1"/>
            </geometry>
            <material name="gray">
                <color rgba="0.5 0.5 0.5 1.0"/>
            </material>
        </visual>
    </link>
    <joint name="slider_joint" type="prismatic">
        <parent link="base_link"/>
        <child link="slider_link"/>
        <origin xyz="0 0 0.5" rpy="0 0 0"/>
        <axis xyz="1 0 0"/>
        <limit lower="0" upper="0.2" effort="10.0" velocity="0.1"/>
    </joint>

    <!-- Arm attached to the slider -->
    <link name="arm_link">
        <visual>
            <origin xyz="0 0 0.1" rpy="0 0 0"/>
            <geometry>
                <cylinder radius="0.05" length="0.6"/>
            </geometry>
            <material name="green">
                <color rgba="0 1 0 1"/>
            </material>
        </visual>
    </link>
    <joint name="arm_joint" type="revolute">
        <parent link="slider_link"/>
        <child link="arm_link"/>
        <origin xyz="0 0 0.05" rpy="0 0 0"/>
        <axis xyz="0 0 1"/>
        <limit lower="-1.57" upper="1.57" effort="10.0" velocity="1.0"/>
    </joint>

    <!-- Camera mounted at the end of the arm -->
    <link name="camera_link">
        <visual>
            <origin xyz="0 0 0.3" rpy="0 0 0"/>
            <geometry>
                <box size="0.1 0.1 0.1"/>
            </geometry>
            <material name="red">
                <color rgba="1 0 0 1"/>
            </material>
        </visual>
    </link>
    <joint name="camera_joint" type="fixed">
        <parent link="arm_link"/>
        <child link="camera_link"/>
        <origin xyz="0 0 0.3" rpy="0 0 0"/>
    </joint>

</robot>
