<?xml version="1.0"?>
<robot xmlns:xacro="http://www.ros.org/wiki/xacro" name="my_robot_wheels">
    <xacro:macro name="wheels" params="wheel_radius wheel_offset_x wheel_offset_y">
        <!-- Front Left Wheel -->
        <link name="wheel_front_left">
            <visual>
                <origin xyz="${wheel_offset_x} ${wheel_offset_y} ${wheel_radius}" rpy="0 1.5708 0"/>
                <geometry>
                    <cylinder radius="${wheel_radius}" length="0.1"/>
                </geometry>
                <material name="gray">
                    <color rgba="0.5 0.5 0.5 1.0"/>
                </material>
            </visual>
        </link>
        <joint name="wheel_joint_front_left" type="continuous">
            <parent link="base_link"/>
            <child link="wheel_front_left"/>
            <origin xyz="${wheel_offset_x} ${wheel_offset_y} ${wheel_radius}" rpy="0 0 0"/>
            <axis xyz="0 1 0"/>
        </joint>

        <!-- Front Right Wheel -->
        <link name="wheel_front_right">
            <visual>
                <origin xyz="${wheel_offset_x} -${wheel_offset_y} ${wheel_radius}" rpy="0 1.5708 0"/>
                <geometry>
                    <cylinder radius="${wheel_radius}" length="0.1"/>
                </geometry>
                <material name="gray">
                    <color rgba="0.5 0.5 0.5 1.0"/>
                </material>
            </visual>
        </link>
        <joint name="wheel_joint_front_right" type="continuous">
            <parent link="base_link"/>
            <child link="wheel_front_right"/>
            <origin xyz="${wheel_offset_x} -${wheel_offset_y} ${wheel_radius}" rpy="0 0 0"/>
            <axis xyz="0 1 0"/>
        </joint>

        <!-- Rear Left Wheel -->
        <link name="wheel_rear_left">
            <visual>
                <origin xyz="-${wheel_offset_x} ${wheel_offset_y} ${wheel_radius}" rpy="0 1.5708 0"/>
                <geometry>
                    <cylinder radius="${wheel_radius}" length="0.1"/>
                </geometry>
                <material name="gray">
                    <color rgba="0.5 0.5 0.5 1.0"/>
                </material>
            </visual>
        </link>
        <joint name="wheel_joint_rear_left" type="continuous">
            <parent link="base_link"/>
            <child link="wheel_rear_left"/>
            <origin xyz="-${wheel_offset_x} ${wheel_offset_y} ${wheel_radius}" rpy="0 0 0"/>
            <axis xyz="0 1 0"/>
        </joint>

        <!-- Rear Right Wheel -->
        <link name="wheel_rear_right">
            <visual>
                <origin xyz="-${wheel_offset_x} -${wheel_offset_y} ${wheel_radius}" rpy="0 1.5708 0"/>
                <geometry>
                    <cylinder radius="${wheel_radius}" length="0.1"/>
                </geometry>
                <material name="gray">
                    <color rgba="0.5 0.5 0.5 1.0"/>
                </material>
            </visual>
        </link>
        <joint name="wheel_joint_rear_right" type="continuous">
            <parent link="base_link"/>
            <child link="wheel_rear_right"/>
            <origin xyz="-${wheel_offset_x} -${wheel_offset_y} ${wheel_radius}" rpy="0 0 0"/>
            <axis xyz="0 1 0"/>
        </joint>
    </xacro:macro>
</robot>
